<sdf version='1.7'>
  <world name='default'>
    <light name='sun' type='directional'>
      <cast_shadows>1</cast_shadows>
      <pose>0 0 10 0 -0 0</pose>
      <diffuse>0.8 0.8 0.8 1</diffuse>
      <specular>0.2 0.2 0.2 1</specular>
      <attenuation>
        <range>1000</range>
        <constant>0.9</constant>
        <linear>0.01</linear>
        <quadratic>0.001</quadratic>
      </attenuation>
      <direction>-0.5 0.1 -0.9</direction>
      <spot>
        <inner_angle>0</inner_angle>
        <outer_angle>0</outer_angle>
        <falloff>0</falloff>
      </spot>
    </light>
    <model name='ground_plane'>
      <static>1</static>
      <link name='link'>
        <collision name='collision'>
          <geometry>
            <plane>
              <normal>0 0 1</normal>
              <size>100 100</size>
            </plane>
          </geometry>
          <surface>
            <contact>
              <collide_bitmask>65535</collide_bitmask>
              <ode/>
            </contact>
            <friction>
              <ode>
                <mu>100</mu>
                <mu2>50</mu2>
              </ode>
              <torsional>
                <ode/>
              </torsional>
            </friction>
            <bounce/>
          </surface>
          <max_contacts>10</max_contacts>
        </collision>
        <visual name='visual'>
          <cast_shadows>0</cast_shadows>
          <geometry>
            <plane>
              <normal>0 0 1</normal>
              <size>100 100</size>
            </plane>
          </geometry>
          <material>
            <script>
              <uri>file://media/materials/scripts/gazebo.material</uri>
              <name>Gazebo/Grey</name>
            </script>
          </material>
        </visual>
        <self_collide>0</self_collide>
        <enable_wind>0</enable_wind>
        <kinematic>0</kinematic>
      </link>
    </model>
    <gravity>0 0 -9.8</gravity>
    <magnetic_field>6e-06 2.3e-05 -4.2e-05</magnetic_field>
    <atmosphere type='adiabatic'/>
    <physics type='ode'>
      <max_step_size>0.001</max_step_size>
      <real_time_factor>1</real_time_factor>
      <real_time_update_rate>1000</real_time_update_rate>
    </physics>
    <scene>
      <ambient>0.4 0.4 0.4 1</ambient>
      <background>0.7 0.7 0.7 1</background>
      <shadows>1</shadows>
    </scene>
    <audio>
      <device>default</device>
    </audio>
    <wind/>
    <spherical_coordinates>
      <surface_model>EARTH_WGS84</surface_model>
      <latitude_deg>0</latitude_deg>
      <longitude_deg>0</longitude_deg>
      <elevation>0</elevation>
      <heading_deg>0</heading_deg>
    </spherical_coordinates>
    <model name='unit_box_1'>
      <pose>-2.31175 2.43831 0.5 0 -0 0</pose>
      <link name='link'>
        <inertial>
          <mass>1</mass>
          <inertia>
            <ixx>0.166667</ixx>
            <ixy>0</ixy>
            <ixz>0</ixz>
            <iyy>0.166667</iyy>
            <iyz>0</iyz>
            <izz>0.166667</izz>
          </inertia>
          <pose>0 0 0 0 -0 0</pose>
        </inertial>
        <collision name='collision'>
          <geometry>
            <box>
              <size>3.67392 1 1</size>
            </box>
          </geometry>
          <max_contacts>10</max_contacts>
          <surface>
            <contact>
              <ode/>
            </contact>
            <bounce/>
            <friction>
              <torsional>
                <ode/>
              </torsional>
              <ode/>
            </friction>
          </surface>
        </collision>
        <visual name='visual'>
          <geometry>
            <box>
              <size>3.67392 1 1</size>
            </box>
          </geometry>
          <material>
            <script>
              <name>Gazebo/Grey</name>
              <uri>file://media/materials/scripts/gazebo.material</uri>
            </script>
          </material>
        </visual>
        <self_collide>0</self_collide>
        <enable_wind>0</enable_wind>
        <kinematic>0</kinematic>
      </link>
      <static>1</static>
    </model>
    <model name='unit_sphere'>
      <pose>-2.81866 8.95253 0.5 0 -0 0</pose>
      <link name='link'>
        <inertial>
          <mass>1</mass>
          <inertia>
            <ixx>0.1</ixx>
            <ixy>0</ixy>
            <ixz>0</ixz>
            <iyy>0.1</iyy>
            <iyz>0</iyz>
            <izz>0.1</izz>
          </inertia>
          <pose>0 0 0 0 -0 0</pose>
        </inertial>
        <collision name='collision'>
          <geometry>
            <sphere>
              <radius>0.5</radius>
            </sphere>
          </geometry>
          <max_contacts>10</max_contacts>
          <surface>
            <contact>
              <ode/>
            </contact>
            <bounce/>
            <friction>
              <torsional>
                <ode/>
              </torsional>
              <ode/>
            </friction>
          </surface>
        </collision>
        <visual name='visual'>
          <geometry>
            <sphere>
              <radius>0.5</radius>
            </sphere>
          </geometry>
          <material>
            <script>
              <name>Gazebo/Grey</name>
              <uri>file://media/materials/scripts/gazebo.material</uri>
            </script>
          </material>
        </visual>
        <self_collide>0</self_collide>
        <enable_wind>0</enable_wind>
        <kinematic>0</kinematic>
      </link>
      <static>1</static>
    </model>
    <model name='unit_box_2'>
      <pose>2.88182 4.3171 0.5 0 -0 0</pose>
      <link name='link'>
        <inertial>
          <mass>1</mass>
          <inertia>
            <ixx>0.166667</ixx>
            <ixy>0</ixy>
            <ixz>0</ixz>
            <iyy>0.166667</iyy>
            <iyz>0</iyz>
            <izz>0.166667</izz>
          </inertia>
          <pose>0 0 0 0 -0 0</pose>
        </inertial>
        <collision name='collision'>
          <geometry>
            <box>
              <size>8.43972 0.358049 1</size>
            </box>
          </geometry>
          <max_contacts>10</max_contacts>
          <surface>
            <contact>
              <ode/>
            </contact>
            <bounce/>
            <friction>
              <torsional>
                <ode/>
              </torsional>
              <ode/>
            </friction>
          </surface>
        </collision>
        <visual name='visual'>
          <geometry>
            <box>
              <size>8.43972 0.358049 1</size>
            </box>
          </geometry>
          <material>
            <script>
              <name>Gazebo/Grey</name>
              <uri>file://media/materials/scripts/gazebo.material</uri>
            </script>
          </material>
        </visual>
        <self_collide>0</self_collide>
        <enable_wind>0</enable_wind>
        <kinematic>0</kinematic>
      </link>
      <static>1</static>
    </model>
    <state world_name='default'>
      <sim_time>1092 958000000</sim_time>
      <real_time>145 920431538</real_time>
      <wall_time>1740507245 21180227</wall_time>
      <iterations>143858</iterations>
      <model name='go2'>
        <pose>-0.13781 -2.13178 0.211433 0.008836 -0.019186 1.53425</pose>
        <scale>1 1 1</scale>
        <link name='base_link'>
          <pose>-0.13781 -2.13178 0.211433 0.008836 -0.019186 1.53425</pose>
          <velocity>-0.082503 0.160297 -0.191177 -0.891094 -0.123925 -0.636919</velocity>
          <acceleration>-2.33424 -5.52701 -2.23479 -2.03515 -0.878284 1.18798</acceleration>
          <wrench>-16.391 -38.8106 -15.6927 0 -0 0</wrench>
        </link>
        <link name='lf_hip_link'>
          <pose>-0.177212 -1.93685 0.215553 0.025201 -0.01918 1.53441</pose>
          <velocity>0.04119 0.189207 -0.369766 -0.875416 0.304276 -0.616868</velocity>
          <acceleration>-5.55795 -6.41173 -8.70378 -0.759712 -1.23367 1.55099</acceleration>
          <wrench>-3.76829 -4.34715 -5.90116 0 -0 0</wrench>
        </link>
        <link name='lf_lower_leg_link'>
          <pose>-0.281962 -2.1057 0.093066 0.067132 -1.15661 1.47293</pose>
          <velocity>-0.101225 0.145419 -0.186174 1.03331 0.24438 -0.648109</velocity>
          <acceleration>7.3854 106.862 933.477 1.39752 -1.23626 2.8094</acceleration>
          <wrench>1.58048 22.8684 199.764 0 -0 0</wrench>
        </link>
        <link name='lf_upper_leg_link'>
          <pose>-0.272619 -1.9334 0.217942 0.04295 0.943672 1.5697</pose>
          <velocity>0.044185 0.252069 -0.343974 -0.900002 0.305862 -0.618234</velocity>
          <acceleration>-3.40718 -26.596 27.014 -0.177513 0.309031 -2.86721</acceleration>
          <wrench>-3.92507 -30.6386 31.1201 0 -0 0</wrench>
        </link>
        <link name='lh_hip_link'>
          <pose>-0.191342 -2.32332 0.208132 -0.027335 -0.019196 1.53427</pose>
          <velocity>-0.204119 0.191276 -0.026886 2.19036 -1.37601 2.45069</velocity>
          <acceleration>1.74293 -6.32753 -0.519981 1.7061 -1.16581 2.68138</acceleration>
          <wrench>1.18171 -4.29007 -0.352547 0 -0 0</wrench>
        </link>
        <link name='lh_lower_leg_link'>
          <pose>-0.291779 -2.51625 0.123394 -0.049118 -1.01539 1.57497</pose>
          <velocity>-0.201986 0.015485 0.368298 -1.39491 -1.23805 2.46016</velocity>
          <acceleration>-14.8867 23.8962 12.371 -3.07509 0.961285 1.12838</acceleration>
          <wrench>-3.18575 5.11378 2.64738 0 -0 0</wrench>
        </link>
        <link name='lh_upper_leg_link'>
          <pose>-0.286741 -2.31978 0.205503 -0.070744 1.17402 1.4685</pose>
          <velocity>-0.197005 0.251456 -0.195672 0.223994 -1.44617 2.39892</velocity>
          <acceleration>0.889263 -6.94237 2.67515 -1.98635 -1.18783 -2.70159</acceleration>
          <wrench>1.02443 -7.99761 3.08177 0 -0 0</wrench>
        </link>
        <link name='rf_hip_link'>
          <pose>-0.084278 -1.94023 0.214733 0.07638 -0.019187 1.53423</pose>
          <velocity>0.039074 0.129311 -0.355268 -0.929035 -1.17992 -0.655522</velocity>
          <acceleration>-5.91315 -4.50796 -2.67986 -1.72153 0.162626 -2.16865</acceleration>
          <wrench>-4.00911 -3.05639 -1.81694 0 -0 0</wrench>
        </link>
        <link name='rf_lower_leg_link'>
          <pose>-0.002999 -2.13425 0.113536 0.161936 -1.07601 1.39283</pose>
          <velocity>0.052934 -0.190952 0.268029 2.90186 -1.14549 -0.450688</velocity>
          <acceleration>-4.2046 23.1063 4.11759 1.23845 -1.38623 -0.319213</acceleration>
          <wrench>-0.899783 4.94474 0.881164 0 -0 0</wrench>
        </link>
        <link name='rf_upper_leg_link'>
          <pose>0.010885 -1.94357 0.207453 0.171321 1.10687 1.68922</pose>
          <velocity>0.045628 0.060535 -0.240863 -2.75229 -1.1162 -0.51582</velocity>
          <acceleration>-5.68867 -1.63455 -5.18569 -2.59445 -0.697185 2.11179</acceleration>
          <wrench>-6.55334 -1.88301 -5.97391 0 -0 0</wrench>
        </link>
        <link name='rh_hip_link'>
          <pose>-0.098407 -2.3267 0.207312 0.003631 -0.019188 1.53423</pose>
          <velocity>-0.206072 0.13138 -0.012675 -0.915201 -0.779435 -0.645533</velocity>
          <acceleration>1.8302 -4.50807 4.12182 2.83847 -0.68621 -0.480641</acceleration>
          <wrench>1.24088 -3.05647 2.7946 0 -0 0</wrench>
        </link>
        <link name='rh_lower_leg_link'>
          <pose>-0.009614 -2.49961 0.078061 0.014607 -1.23354 1.52029</pose>
          <velocity>-0.216728 -0.108649 0.299237 -1.4218 -0.328665 -0.964147</velocity>
          <acceleration>-5.18356 373.199 1220 -1.62872 -1.13407 3.00502</acceleration>
          <wrench>-1.10928 79.8646 261.079 0 -0 0</wrench>
        </link>
        <link name='rh_upper_leg_link'>
          <pose>-0.002971 -2.33019 0.206978 0.005885 0.920707 1.53904</pose>
          <velocity>-0.207917 0.069272 0.06598 -1.40732 -0.762545 -0.655497</velocity>
          <acceleration>-2.87049 -2.87377 -14.5945 1.4079 0.837001 1.10851</acceleration>
          <wrench>-3.30681 -3.31058 -16.8129 0 -0 0</wrench>
        </link>
      </model>
      <model name='ground_plane'>
        <pose>0 0 0 0 -0 0</pose>
        <scale>1 1 1</scale>
        <link name='link'>
          <pose>0 0 0 0 -0 0</pose>
          <velocity>0 0 0 0 -0 0</velocity>
          <acceleration>0 0 0 0 -0 0</acceleration>
          <wrench>0 0 0 0 -0 0</wrench>
        </link>
      </model>
      <model name='unit_box_1'>
        <pose>0.196842 1.30829 0.5 0 0 -2e-06</pose>
        <scale>0.648073 1 1</scale>
        <link name='link'>
          <pose>0.196842 1.30829 0.5 0 0 -2e-06</pose>
          <velocity>0 0 0 0 -0 0</velocity>
          <acceleration>0 0 0 0 -0 0</acceleration>
          <wrench>0 0 0 0 -0 0</wrench>
        </link>
      </model>
      <model name='unit_box_2'>
        <pose>2.40037 3.98226 0.5 0 -0 0</pose>
        <scale>0.491161 1.40827 1</scale>
        <link name='link'>
          <pose>2.40037 3.98226 0.5 0 -0 0</pose>
          <velocity>0 0 0 0 -0 0</velocity>
          <acceleration>0 0 0 0 -0 0</acceleration>
          <wrench>0 0 0 0 -0 0</wrench>
        </link>
      </model>
      <model name='unit_box_4'>
        <pose>1.88733 0.877472 0.354333 0 1e-05 -6e-06</pose>
        <scale>1 0.730235 1.18789</scale>
        <link name='link'>
          <pose>1.88733 0.877472 0.354333 0 1e-05 -6e-06</pose>
          <velocity>0 0 0 0 -0 0</velocity>
          <acceleration>0.015316 -0.005757 -9.77628 0.016632 0.038588 0.000588</acceleration>
          <wrench>0.015316 -0.005757 -9.77628 0 -0 0</wrench>
        </link>
      </model>
      <model name='unit_sphere'>
        <pose>-2.81866 8.95253 0.5 0 -0 0</pose>
        <scale>1 1 1</scale>
        <link name='link'>
          <pose>-2.81866 8.95253 0.5 0 -0 0</pose>
          <velocity>0 0 0 0 -0 0</velocity>
          <acceleration>0 0 0 0 -0 0</acceleration>
          <wrench>0 0 0 0 -0 0</wrench>
        </link>
      </model>
      <light name='sun'>
        <pose>0 0 10 0 -0 0</pose>
      </light>
    </state>
    <gui fullscreen='0'>
      <camera name='user_camera'>
        <pose>5.07219 -0.167649 11.2292 0 1.0948 2.54</pose>
        <view_controller>orbit</view_controller>
        <projection_type>perspective</projection_type>
      </camera>
    </gui>
    <model name='unit_box_4'>
      <pose>-2.38145 -3.13109 0.5 0 -0 0</pose>
      <link name='link'>
        <inertial>
          <mass>1</mass>
          <inertia>
            <ixx>0.166667</ixx>
            <ixy>0</ixy>
            <ixz>0</ixz>
            <iyy>0.166667</iyy>
            <iyz>0</iyz>
            <izz>0.166667</izz>
          </inertia>
          <pose>0 0 0 0 -0 0</pose>
        </inertial>
        <collision name='collision'>
          <geometry>
            <box>
              <size>1 2.56809 0.596584</size>
            </box>
          </geometry>
          <max_contacts>10</max_contacts>
          <surface>
            <contact>
              <ode/>
            </contact>
            <bounce/>
            <friction>
              <torsional>
                <ode/>
              </torsional>
              <ode/>
            </friction>
          </surface>
        </collision>
        <visual name='visual'>
          <geometry>
            <box>
              <size>1 2.56809 0.596584</size>
            </box>
          </geometry>
          <material>
            <script>
              <name>Gazebo/Grey</name>
              <uri>file://media/materials/scripts/gazebo.material</uri>
            </script>
          </material>
        </visual>
        <self_collide>0</self_collide>
        <enable_wind>0</enable_wind>
        <kinematic>0</kinematic>
      </link>
    </model>
    <model name='go2'>
      <link name='base_link'>
        <inertial>
          <pose>0.023657 0 -0.003865 0 -0 0</pose>
          <mass>7.022</mass>
          <inertia>
            <ixx>0.0257344</ixx>
            <ixy>0.00012166</ixy>
            <ixz>-0.000373034</ixz>
            <iyy>0.10254</iyy>
            <iyz>-3.12e-05</iyz>
            <izz>0.110368</izz>
          </inertia>
        </inertial>
        <collision name='base_link_fixed_joint_lump__trunk_collision'>
          <pose>0 0 0 0 -0 0</pose>
          <geometry>
            <box>
              <size>0.3762 0.0935 0.114</size>
            </box>
          </geometry>
          <surface>
            <contact>
              <ode>
                <kp>10000</kp>
                <kd>1</kd>
              </ode>
            </contact>
            <friction>
              <ode>
                <mu>0.2</mu>
                <mu2>0.2</mu2>
              </ode>
              <torsional>
                <ode/>
              </torsional>
            </friction>
            <bounce/>
          </surface>
          <max_contacts>10</max_contacts>
        </collision>
        <collision name='base_link_fixed_joint_lump__imu_link_collision_1'>
          <pose>0 0 0 0 -0 0</pose>
          <geometry>
            <box>
              <size>0.001 0.001 0.001</size>
            </box>
          </geometry>
          <surface>
            <contact>
              <ode/>
            </contact>
            <friction>
              <ode/>
              <torsional>
                <ode/>
              </torsional>
            </friction>
            <bounce/>
          </surface>
          <max_contacts>10</max_contacts>
        </collision>
        <visual name='base_link_visual'>
          <pose>0 0 0 0 -0 0</pose>
          <geometry>
            <box>
              <size>0.001 0.001 0.001</size>
            </box>
          </geometry>
        </visual>
        <visual name='base_link_fixed_joint_lump__trunk_visual_1'>
          <pose>0 0 0 0 -0 0</pose>
          <geometry>
            <mesh>
              <scale>1 1 1</scale>
              <uri>file:///workspace/comp0244-go2/install/go2_description/share/go2_description/meshes/trunk.dae</uri>
            </mesh>
          </geometry>
        </visual>
        <visual name='base_link_fixed_joint_lump__imu_link_visual_2'>
          <pose>0 0 0 0 -0 0</pose>
          <geometry>
            <box>
              <size>0.001 0.001 0.001</size>
            </box>
          </geometry>
        </visual>
        <visual name='base_link_fixed_joint_lump__livox_visual_3'>
          <pose>0.2 0 0.1 0 -0 0</pose>
          <geometry>
            <box>
              <size>0.1 0.06 0.06</size>
            </box>
          </geometry>
        </visual>
        <sensor name='imu_sensor' type='imu'>
          <always_on>1</always_on>
          <update_rate>100</update_rate>
          <imu>
            <angular_velocity>
              <x>
                <noise type='gaussian'>
                  <mean>0</mean>
                  <stddev>0.0002</stddev>
                </noise>
              </x>
              <y>
                <noise type='gaussian'>
                  <mean>0</mean>
                  <stddev>0.0002</stddev>
                </noise>
              </y>
              <z>
                <noise type='gaussian'>
                  <mean>0</mean>
                  <stddev>0.0002</stddev>
                </noise>
              </z>
            </angular_velocity>
            <linear_acceleration>
              <x>
                <noise type='gaussian'>
                  <mean>0</mean>
                  <stddev>0.017</stddev>
                </noise>
              </x>
              <y>
                <noise type='gaussian'>
                  <mean>0</mean>
                  <stddev>0.017</stddev>
                </noise>
              </y>
              <z>
                <noise type='gaussian'>
                  <mean>0</mean>
                  <stddev>0.017</stddev>
                </noise>
              </z>
            </linear_acceleration>
          </imu>
          <plugin name='imu_plugin' filename='libgazebo_ros_imu_sensor.so'>
            <ros>
              <namespace>imu</namespace>
              <remapping>~/out:=data</remapping>
            </ros>
            <initial_orientation_as_reference>0</initial_orientation_as_reference>
          </plugin>
          <pose>0 0 0 0 -0 0</pose>
        </sensor>
        <sensor name='livox' type='ray'>
          <visualize>1</visualize>
          <update_rate>10</update_rate>
          <plugin name='livox_plugin' filename='libros2_livox.so'>
            <ray>
              <scan>
                <horizontal>
                  <samples>100</samples>
                  <resolution>1</resolution>
                  <min_angle>0</min_angle>
                  <max_angle>6.2831852</max_angle>
                </horizontal>
                <vertical>
                  <samples>360</samples>
                  <resolution>1</resolution>
                  <min_angle>-0.12601276984444446</min_angle>
                  <max_angle>0.9637707965111111</max_angle>
                </vertical>
              </scan>
              <range>
                <min>0.1</min>
                <max>100.0</max>
                <resolution>0.002</resolution>
              </range>
              <noise>
                <type>gaussian</type>
                <mean>0.0</mean>
                <stddev>0.01</stddev>
              </noise>
            </ray>
            <visualize>1</visualize>
            <samples>20000</samples>
            <downsample>10</downsample>
            <csv_file_name>/workspace/comp0244-go2/install/ros2_livox_simulation/share/ros2_livox_simulation/scan_mode/mid360.csv</csv_file_name>
            <topic>mid360</topic>
          </plugin>
          <pose>0.2 0 0.1 0 -0 0</pose>
          <ray>
            <scan>
              <horizontal>
                <samples>640</samples>
                <resolution>1</resolution>
                <min_angle>0</min_angle>
                <max_angle>0</max_angle>
              </horizontal>
              <vertical>
                <samples>1</samples>
                <min_angle>0</min_angle>
                <max_angle>0</max_angle>
              </vertical>
            </scan>
            <range>
              <min>0</min>
              <max>0</max>
            </range>
          </ray>
        </sensor>
        <self_collide>0</self_collide>
        <enable_wind>0</enable_wind>
        <kinematic>0</kinematic>
      </link>
      <joint name='lf_hip_joint' type='revolute'>
        <pose relative_to='base_link'>0.1934 0.0465 0 0 -0 0</pose>
        <parent>base_link</parent>
        <child>lf_hip_link</child>
        <axis>
          <xyz>1 0 0</xyz>
          <limit>
            <lower>-1.0472</lower>
            <upper>1.0472</upper>
            <effort>23.7</effort>
            <velocity>30.1</velocity>
          </limit>
          <dynamics>
            <damping>0.01</damping>
            <friction>0.2</friction>
            <spring_reference>0</spring_reference>
            <spring_stiffness>0</spring_stiffness>
          </dynamics>
        </axis>
      </joint>
      <link name='lf_hip_link'>
        <pose relative_to='lf_hip_joint'>0 0 0 0 -0 0</pose>
        <inertial>
          <pose>-0.0054 0.00194 -0.000105 0 -0 0</pose>
          <mass>0.678</mass>
          <inertia>
            <ixx>0.00048</ixx>
            <ixy>-3.01e-06</ixy>
            <ixz>1.11e-06</ixz>
            <iyy>0.000884</iyy>
            <iyz>-1.42e-06</iyz>
            <izz>0.000596</izz>
          </inertia>
        </inertial>
        <collision name='lf_hip_link_collision'>
          <pose>0 0.0955 0 1.5708 -0 0</pose>
          <geometry>
            <cylinder>
              <length>0.04</length>
              <radius>0.046</radius>
            </cylinder>
          </geometry>
          <surface>
            <contact>
              <ode/>
            </contact>
            <friction>
              <ode>
                <mu>0.2</mu>
                <mu2>0.2</mu2>
              </ode>
              <torsional>
                <ode/>
              </torsional>
            </friction>
            <bounce/>
          </surface>
          <max_contacts>10</max_contacts>
        </collision>
        <visual name='lf_hip_link_visual'>
          <pose>0 0 0 0 -0 0</pose>
          <geometry>
            <mesh>
              <scale>1 1 1</scale>
              <uri>file:///workspace/comp0244-go2/install/go2_description/share/go2_description/meshes/hip.dae</uri>
            </mesh>
          </geometry>
        </visual>
        <self_collide>0</self_collide>
        <enable_wind>0</enable_wind>
        <kinematic>0</kinematic>
      </link>
      <joint name='lf_upper_leg_joint' type='revolute'>
        <pose relative_to='lf_hip_link'>0 0.0955 0 0 -0 0</pose>
        <parent>lf_hip_link</parent>
        <child>lf_upper_leg_link</child>
        <axis>
          <xyz>0 1 0</xyz>
          <limit>
            <lower>-1.5708</lower>
            <upper>3.4907</upper>
            <effort>23.7</effort>
            <velocity>30.1</velocity>
          </limit>
          <dynamics>
            <damping>0.01</damping>
            <friction>0.2</friction>
            <spring_reference>0</spring_reference>
            <spring_stiffness>0</spring_stiffness>
          </dynamics>
        </axis>
      </joint>
      <link name='lf_upper_leg_link'>
        <pose relative_to='lf_upper_leg_joint'>0 0 0 0 -0 0</pose>
        <inertial>
          <pose>-0.00374 -0.0223 -0.0327 0 -0 0</pose>
          <mass>1.152</mass>
          <inertia>
            <ixx>0.00584</ixx>
            <ixy>8.72e-05</ixy>
            <ixz>-0.000289</ixz>
            <iyy>0.0058</iyy>
            <iyz>0.000808</iyz>
            <izz>0.00103</izz>
          </inertia>
        </inertial>
        <collision name='lf_upper_leg_link_collision'>
          <pose>0 0 -0.1065 3.14159 1.57079 3.14159</pose>
          <geometry>
            <box>
              <size>0.213 0.0245 0.034</size>
            </box>
          </geometry>
          <surface>
            <contact>
              <ode>
                <kp>10000</kp>
                <kd>1</kd>
              </ode>
            </contact>
            <friction>
              <ode>
                <mu>0.2</mu>
                <mu2>0.2</mu2>
              </ode>
              <torsional>
                <ode/>
              </torsional>
            </friction>
            <bounce/>
          </surface>
          <max_contacts>10</max_contacts>
        </collision>
        <visual name='lf_upper_leg_link_visual'>
          <pose>0 0 0 0 -0 0</pose>
          <geometry>
            <mesh>
              <scale>1 1 1</scale>
              <uri>file:///workspace/comp0244-go2/install/go2_description/share/go2_description/meshes/thigh.dae</uri>
            </mesh>
          </geometry>
        </visual>
        <self_collide>1</self_collide>
        <enable_wind>0</enable_wind>
        <kinematic>0</kinematic>
      </link>
      <joint name='lf_lower_leg_joint' type='revolute'>
        <pose relative_to='lf_upper_leg_link'>0 0 -0.213 0 -0 0</pose>
        <parent>lf_upper_leg_link</parent>
        <child>lf_lower_leg_link</child>
        <axis>
          <xyz>0 1 0</xyz>
          <limit>
            <lower>-2.7227</lower>
            <upper>-0.83776</upper>
            <effort>35.55</effort>
            <velocity>20.06</velocity>
          </limit>
          <dynamics>
            <damping>0.01</damping>
            <friction>0.2</friction>
            <spring_reference>0</spring_reference>
            <spring_stiffness>0</spring_stiffness>
          </dynamics>
        </axis>
      </joint>
      <link name='lf_lower_leg_link'>
        <pose relative_to='lf_lower_leg_joint'>0 0 0 0 -0 0</pose>
        <inertial>
          <pose>0.003944 -0.000702 -0.142477 0 -0 0</pose>
          <mass>0.214</mass>
          <inertia>
            <ixx>0.00150432</ixx>
            <ixy>5.70698e-07</ixy>
            <ixz>-5.98808e-06</ixz>
            <iyy>0.00152557</iyy>
            <iyz>1.24056e-05</iyz>
            <izz>4.38377e-05</izz>
          </inertia>
        </inertial>
        <collision name='lf_lower_leg_link_collision'>
          <pose>0 0 -0.1065 3.14159 1.57079 3.14159</pose>
          <geometry>
            <box>
              <size>0.213 0.016 0.016</size>
            </box>
          </geometry>
          <surface>
            <contact>
              <ode/>
            </contact>
            <friction>
              <ode>
                <mu>0.2</mu>
                <mu2>0.2</mu2>
              </ode>
              <torsional>
                <ode/>
              </torsional>
            </friction>
            <bounce/>
          </surface>
          <max_contacts>10</max_contacts>
        </collision>
        <collision name='lf_lower_leg_link_fixed_joint_lump__lf_foot_link_collision_1'>
          <pose>0 0 -0.213 0 -0 0</pose>
          <geometry>
            <sphere>
              <radius>0.02</radius>
            </sphere>
          </geometry>
          <surface>
            <contact>
              <ode>
                <kp>10000</kp>
                <kd>1</kd>
              </ode>
            </contact>
            <friction>
              <ode>
                <mu>0.6</mu>
                <mu2>0.6</mu2>
              </ode>
              <torsional>
                <ode/>
              </torsional>
            </friction>
            <bounce/>
          </surface>
          <max_contacts>10</max_contacts>
        </collision>
        <visual name='lf_lower_leg_link_visual'>
          <pose>0 0 0 0 -0 0</pose>
          <geometry>
            <mesh>
              <scale>1 1 1</scale>
              <uri>file:///workspace/comp0244-go2/install/go2_description/share/go2_description/meshes/calf.dae</uri>
            </mesh>
          </geometry>
        </visual>
        <visual name='lf_lower_leg_link_fixed_joint_lump__lf_foot_link_visual_1'>
          <pose>0 0 -0.213 0 -0 0</pose>
          <geometry>
            <sphere>
              <radius>0.01</radius>
            </sphere>
          </geometry>
        </visual>
        <self_collide>1</self_collide>
        <self_collide>1</self_collide>
        <enable_wind>0</enable_wind>
        <kinematic>0</kinematic>
      </link>
      <joint name='lh_hip_joint' type='revolute'>
        <pose relative_to='base_link'>-0.1934 0.0465 0 0 -0 0</pose>
        <parent>base_link</parent>
        <child>lh_hip_link</child>
        <axis>
          <xyz>1 0 0</xyz>
          <limit>
            <lower>-1.0472</lower>
            <upper>1.0472</upper>
            <effort>23.7</effort>
            <velocity>30.1</velocity>
          </limit>
          <dynamics>
            <damping>0.01</damping>
            <friction>0.2</friction>
            <spring_reference>0</spring_reference>
            <spring_stiffness>0</spring_stiffness>
          </dynamics>
        </axis>
      </joint>
      <link name='lh_hip_link'>
        <pose relative_to='lh_hip_joint'>0 0 0 0 -0 0</pose>
        <inertial>
          <pose>0.0054 0.00194 -0.000105 0 -0 0</pose>
          <mass>0.678</mass>
          <inertia>
            <ixx>0.00048</ixx>
            <ixy>3.01e-06</ixy>
            <ixz>-1.11e-06</ixz>
            <iyy>0.000884</iyy>
            <iyz>-1.42e-06</iyz>
            <izz>0.000596</izz>
          </inertia>
        </inertial>
        <collision name='lh_hip_link_collision'>
          <pose>0 0.0955 0 1.5708 -0 0</pose>
          <geometry>
            <cylinder>
              <length>0.04</length>
              <radius>0.046</radius>
            </cylinder>
          </geometry>
          <max_contacts>10</max_contacts>
          <surface>
            <contact>
              <ode/>
            </contact>
            <bounce/>
            <friction>
              <torsional>
                <ode/>
              </torsional>
              <ode/>
            </friction>
          </surface>
        </collision>
        <visual name='lh_hip_link_visual'>
          <pose>0 0 0 3.14159 -0 3.14159</pose>
          <geometry>
            <mesh>
              <scale>1 1 1</scale>
              <uri>file:///workspace/comp0244-go2/install/go2_description/share/go2_description/meshes/hip.dae</uri>
            </mesh>
          </geometry>
        </visual>
        <self_collide>0</self_collide>
        <enable_wind>0</enable_wind>
        <kinematic>0</kinematic>
      </link>
      <joint name='lh_upper_leg_joint' type='revolute'>
        <pose relative_to='lh_hip_link'>0 0.0955 0 0 -0 0</pose>
        <parent>lh_hip_link</parent>
        <child>lh_upper_leg_link</child>
        <axis>
          <xyz>0 1 0</xyz>
          <limit>
            <lower>-1.5708</lower>
            <upper>3.4907</upper>
            <effort>23.7</effort>
            <velocity>30.1</velocity>
          </limit>
          <dynamics>
            <damping>0.01</damping>
            <friction>0.2</friction>
            <spring_reference>0</spring_reference>
            <spring_stiffness>0</spring_stiffness>
          </dynamics>
        </axis>
      </joint>
      <link name='lh_upper_leg_link'>
        <pose relative_to='lh_upper_leg_joint'>0 0 0 0 -0 0</pose>
        <inertial>
          <pose>-0.00374 -0.0223 -0.0327 0 -0 0</pose>
          <mass>1.152</mass>
          <inertia>
            <ixx>0.00584</ixx>
            <ixy>8.72e-05</ixy>
            <ixz>-0.000289</ixz>
            <iyy>0.0058</iyy>
            <iyz>0.000808</iyz>
            <izz>0.00103</izz>
          </inertia>
        </inertial>
        <collision name='lh_upper_leg_link_collision'>
          <pose>0 0 -0.1065 3.14159 1.57079 3.14159</pose>
          <geometry>
            <box>
              <size>0.213 0.0245 0.034</size>
            </box>
          </geometry>
          <surface>
            <contact>
              <ode>
                <kp>10000</kp>
                <kd>1</kd>
              </ode>
            </contact>
            <friction>
              <ode>
                <mu>0.2</mu>
                <mu2>0.2</mu2>
              </ode>
              <torsional>
                <ode/>
              </torsional>
            </friction>
            <bounce/>
          </surface>
          <max_contacts>10</max_contacts>
        </collision>
        <visual name='lh_upper_leg_link_visual'>
          <pose>0 0 0 0 -0 0</pose>
          <geometry>
            <mesh>
              <scale>1 1 1</scale>
              <uri>file:///workspace/comp0244-go2/install/go2_description/share/go2_description/meshes/thigh.dae</uri>
            </mesh>
          </geometry>
        </visual>
        <self_collide>1</self_collide>
        <enable_wind>0</enable_wind>
        <kinematic>0</kinematic>
      </link>
      <joint name='lh_lower_leg_joint' type='revolute'>
        <pose relative_to='lh_upper_leg_link'>0 0 -0.213 0 -0 0</pose>
        <parent>lh_upper_leg_link</parent>
        <child>lh_lower_leg_link</child>
        <axis>
          <xyz>0 1 0</xyz>
          <limit>
            <lower>-2.7227</lower>
            <upper>-0.83776</upper>
            <effort>35.55</effort>
            <velocity>20.06</velocity>
          </limit>
          <dynamics>
            <damping>0.01</damping>
            <friction>0.2</friction>
            <spring_reference>0</spring_reference>
            <spring_stiffness>0</spring_stiffness>
          </dynamics>
        </axis>
      </joint>
      <link name='lh_lower_leg_link'>
        <pose relative_to='lh_lower_leg_joint'>0 0 0 0 -0 0</pose>
        <inertial>
          <pose>0.003944 -0.000702 -0.142477 0 -0 0</pose>
          <mass>0.214</mass>
          <inertia>
            <ixx>0.00150432</ixx>
            <ixy>5.70698e-07</ixy>
            <ixz>-5.98808e-06</ixz>
            <iyy>0.00152557</iyy>
            <iyz>1.24056e-05</iyz>
            <izz>4.38377e-05</izz>
          </inertia>
        </inertial>
        <collision name='lh_lower_leg_link_collision'>
          <pose>0 0 -0.1065 3.14159 1.57079 3.14159</pose>
          <geometry>
            <box>
              <size>0.213 0.016 0.016</size>
            </box>
          </geometry>
          <surface>
            <contact>
              <ode/>
            </contact>
            <friction>
              <ode>
                <mu>0.2</mu>
                <mu2>0.2</mu2>
              </ode>
              <torsional>
                <ode/>
              </torsional>
            </friction>
            <bounce/>
          </surface>
          <max_contacts>10</max_contacts>
        </collision>
        <collision name='lh_lower_leg_link_fixed_joint_lump__lh_foot_link_collision_1'>
          <pose>0 0 -0.213 0 -0 0</pose>
          <geometry>
            <sphere>
              <radius>0.02</radius>
            </sphere>
          </geometry>
          <surface>
            <contact>
              <ode>
                <kp>10000</kp>
                <kd>1</kd>
              </ode>
            </contact>
            <friction>
              <ode>
                <mu>0.6</mu>
                <mu2>0.6</mu2>
              </ode>
              <torsional>
                <ode/>
              </torsional>
            </friction>
            <bounce/>
          </surface>
          <max_contacts>10</max_contacts>
        </collision>
        <visual name='lh_lower_leg_link_visual'>
          <pose>0 0 0 0 -0 0</pose>
          <geometry>
            <mesh>
              <scale>1 1 1</scale>
              <uri>file:///workspace/comp0244-go2/install/go2_description/share/go2_description/meshes/calf.dae</uri>
            </mesh>
          </geometry>
        </visual>
        <visual name='lh_lower_leg_link_fixed_joint_lump__lh_foot_link_visual_1'>
          <pose>0 0 -0.213 0 -0 0</pose>
          <geometry>
            <sphere>
              <radius>0.01</radius>
            </sphere>
          </geometry>
        </visual>
        <self_collide>1</self_collide>
        <self_collide>1</self_collide>
        <enable_wind>0</enable_wind>
        <kinematic>0</kinematic>
      </link>
      <joint name='rf_hip_joint' type='revolute'>
        <pose relative_to='base_link'>0.1934 -0.0465 0 0 -0 0</pose>
        <parent>base_link</parent>
        <child>rf_hip_link</child>
        <axis>
          <xyz>1 0 0</xyz>
          <limit>
            <lower>-1.0472</lower>
            <upper>1.0472</upper>
            <effort>23.7</effort>
            <velocity>30.1</velocity>
          </limit>
          <dynamics>
            <damping>0.01</damping>
            <friction>0.2</friction>
            <spring_reference>0</spring_reference>
            <spring_stiffness>0</spring_stiffness>
          </dynamics>
        </axis>
      </joint>
      <link name='rf_hip_link'>
        <pose relative_to='rf_hip_joint'>0 0 0 0 -0 0</pose>
        <inertial>
          <pose>-0.0054 -0.00194 -0.000105 0 -0 0</pose>
          <mass>0.678</mass>
          <inertia>
            <ixx>0.00048</ixx>
            <ixy>3.01e-06</ixy>
            <ixz>1.11e-06</ixz>
            <iyy>0.000884</iyy>
            <iyz>1.42e-06</iyz>
            <izz>0.000596</izz>
          </inertia>
        </inertial>
        <collision name='rf_hip_link_collision'>
          <pose>0 -0.0955 0 1.5708 -0 0</pose>
          <geometry>
            <cylinder>
              <length>0.04</length>
              <radius>0.046</radius>
            </cylinder>
          </geometry>
          <max_contacts>10</max_contacts>
          <surface>
            <contact>
              <ode/>
            </contact>
            <bounce/>
            <friction>
              <torsional>
                <ode/>
              </torsional>
              <ode/>
            </friction>
          </surface>
        </collision>
        <visual name='rf_hip_link_visual'>
          <pose>0 0 0 3.14159 -0 0</pose>
          <geometry>
            <mesh>
              <scale>1 1 1</scale>
              <uri>file:///workspace/comp0244-go2/install/go2_description/share/go2_description/meshes/hip.dae</uri>
            </mesh>
          </geometry>
        </visual>
        <self_collide>0</self_collide>
        <enable_wind>0</enable_wind>
        <kinematic>0</kinematic>
      </link>
      <joint name='rf_upper_leg_joint' type='revolute'>
        <pose relative_to='rf_hip_link'>0 -0.0955 0 0 -0 0</pose>
        <parent>rf_hip_link</parent>
        <child>rf_upper_leg_link</child>
        <axis>
          <xyz>0 1 0</xyz>
          <limit>
            <lower>-1.5708</lower>
            <upper>3.4907</upper>
            <effort>23.7</effort>
            <velocity>30.1</velocity>
          </limit>
          <dynamics>
            <damping>0.01</damping>
            <friction>0.2</friction>
            <spring_reference>0</spring_reference>
            <spring_stiffness>0</spring_stiffness>
          </dynamics>
        </axis>
      </joint>
      <link name='rf_upper_leg_link'>
        <pose relative_to='rf_upper_leg_joint'>0 0 0 0 -0 0</pose>
        <inertial>
          <pose>-0.00374 0.0223 -0.0327 0 -0 0</pose>
          <mass>1.152</mass>
          <inertia>
            <ixx>0.00584</ixx>
            <ixy>-8.72e-05</ixy>
            <ixz>-0.000289</ixz>
            <iyy>0.0058</iyy>
            <iyz>-0.000808</iyz>
            <izz>0.00103</izz>
          </inertia>
        </inertial>
        <collision name='rf_upper_leg_link_collision'>
          <pose>0 0 -0.1065 3.14159 1.57079 3.14159</pose>
          <geometry>
            <box>
              <size>0.213 0.0245 0.034</size>
            </box>
          </geometry>
          <surface>
            <contact>
              <ode>
                <kp>10000</kp>
                <kd>1</kd>
              </ode>
            </contact>
            <friction>
              <ode>
                <mu>0.2</mu>
                <mu2>0.2</mu2>
              </ode>
              <torsional>
                <ode/>
              </torsional>
            </friction>
            <bounce/>
          </surface>
          <max_contacts>10</max_contacts>
        </collision>
        <visual name='rf_upper_leg_link_visual'>
          <pose>0 0 0 0 -0 0</pose>
          <geometry>
            <mesh>
              <scale>1 1 1</scale>
              <uri>file:///workspace/comp0244-go2/install/go2_description/share/go2_description/meshes/thigh_mirror.dae</uri>
            </mesh>
          </geometry>
        </visual>
        <self_collide>1</self_collide>
        <enable_wind>0</enable_wind>
        <kinematic>0</kinematic>
      </link>
      <joint name='rf_lower_leg_joint' type='revolute'>
        <pose relative_to='rf_upper_leg_link'>0 0 -0.213 0 -0 0</pose>
        <parent>rf_upper_leg_link</parent>
        <child>rf_lower_leg_link</child>
        <axis>
          <xyz>0 1 0</xyz>
          <limit>
            <lower>-2.7227</lower>
            <upper>-0.83776</upper>
            <effort>35.55</effort>
            <velocity>20.06</velocity>
          </limit>
          <dynamics>
            <damping>0.01</damping>
            <friction>0.2</friction>
            <spring_reference>0</spring_reference>
            <spring_stiffness>0</spring_stiffness>
          </dynamics>
        </axis>
      </joint>
      <link name='rf_lower_leg_link'>
        <pose relative_to='rf_lower_leg_joint'>0 0 0 0 -0 0</pose>
        <inertial>
          <pose>0.003944 -0.000702 -0.142477 0 -0 0</pose>
          <mass>0.214</mass>
          <inertia>
            <ixx>0.00150432</ixx>
            <ixy>5.70698e-07</ixy>
            <ixz>-5.98808e-06</ixz>
            <iyy>0.00152557</iyy>
            <iyz>1.24056e-05</iyz>
            <izz>4.38377e-05</izz>
          </inertia>
        </inertial>
        <collision name='rf_lower_leg_link_collision'>
          <pose>0 0 -0.1065 3.14159 1.57079 3.14159</pose>
          <geometry>
            <box>
              <size>0.213 0.016 0.016</size>
            </box>
          </geometry>
          <surface>
            <contact>
              <ode/>
            </contact>
            <friction>
              <ode>
                <mu>0.2</mu>
                <mu2>0.2</mu2>
              </ode>
              <torsional>
                <ode/>
              </torsional>
            </friction>
            <bounce/>
          </surface>
          <max_contacts>10</max_contacts>
        </collision>
        <collision name='rf_lower_leg_link_fixed_joint_lump__rf_foot_link_collision_1'>
          <pose>0 0 -0.213 0 -0 0</pose>
          <geometry>
            <sphere>
              <radius>0.02</radius>
            </sphere>
          </geometry>
          <surface>
            <contact>
              <ode>
                <kp>10000</kp>
                <kd>1</kd>
              </ode>
            </contact>
            <friction>
              <ode>
                <mu>0.6</mu>
                <mu2>0.6</mu2>
              </ode>
              <torsional>
                <ode/>
              </torsional>
            </friction>
            <bounce/>
          </surface>
          <max_contacts>10</max_contacts>
        </collision>
        <visual name='rf_lower_leg_link_visual'>
          <pose>0 0 0 0 -0 0</pose>
          <geometry>
            <mesh>
              <scale>1 1 1</scale>
              <uri>file:///workspace/comp0244-go2/install/go2_description/share/go2_description/meshes/calf.dae</uri>
            </mesh>
          </geometry>
        </visual>
        <visual name='rf_lower_leg_link_fixed_joint_lump__rf_foot_link_visual_1'>
          <pose>0 0 -0.213 0 -0 0</pose>
          <geometry>
            <sphere>
              <radius>0.01</radius>
            </sphere>
          </geometry>
        </visual>
        <self_collide>1</self_collide>
        <self_collide>1</self_collide>
        <enable_wind>0</enable_wind>
        <kinematic>0</kinematic>
      </link>
      <joint name='rh_hip_joint' type='revolute'>
        <pose relative_to='base_link'>-0.1934 -0.0465 0 0 -0 0</pose>
        <parent>base_link</parent>
        <child>rh_hip_link</child>
        <axis>
          <xyz>1 0 0</xyz>
          <limit>
            <lower>-1.0472</lower>
            <upper>1.0472</upper>
            <effort>23.7</effort>
            <velocity>30.1</velocity>
          </limit>
          <dynamics>
            <damping>0.01</damping>
            <friction>0.2</friction>
            <spring_reference>0</spring_reference>
            <spring_stiffness>0</spring_stiffness>
          </dynamics>
        </axis>
      </joint>
      <link name='rh_hip_link'>
        <pose relative_to='rh_hip_joint'>0 0 0 0 -0 0</pose>
        <inertial>
          <pose>0.0054 -0.00194 -0.000105 0 -0 0</pose>
          <mass>0.678</mass>
          <inertia>
            <ixx>0.00048</ixx>
            <ixy>-3.01e-06</ixy>
            <ixz>-1.11e-06</ixz>
            <iyy>0.000884</iyy>
            <iyz>1.42e-06</iyz>
            <izz>0.000596</izz>
          </inertia>
        </inertial>
        <collision name='rh_hip_link_collision'>
          <pose>0 -0.0955 0 1.5708 -0 0</pose>
          <geometry>
            <cylinder>
              <length>0.04</length>
              <radius>0.046</radius>
            </cylinder>
          </geometry>
          <max_contacts>10</max_contacts>
          <surface>
            <contact>
              <ode/>
            </contact>
            <bounce/>
            <friction>
              <torsional>
                <ode/>
              </torsional>
              <ode/>
            </friction>
          </surface>
        </collision>
        <visual name='rh_hip_link_visual'>
          <pose>0 0 0 0 -0 3.14159</pose>
          <geometry>
            <mesh>
              <scale>1 1 1</scale>
              <uri>file:///workspace/comp0244-go2/install/go2_description/share/go2_description/meshes/hip.dae</uri>
            </mesh>
          </geometry>
        </visual>
        <self_collide>0</self_collide>
        <enable_wind>0</enable_wind>
        <kinematic>0</kinematic>
      </link>
      <joint name='rh_upper_leg_joint' type='revolute'>
        <pose relative_to='rh_hip_link'>0 -0.0955 0 0 -0 0</pose>
        <parent>rh_hip_link</parent>
        <child>rh_upper_leg_link</child>
        <axis>
          <xyz>0 1 0</xyz>
          <limit>
            <lower>-1.5708</lower>
            <upper>3.4907</upper>
            <effort>23.7</effort>
            <velocity>30.1</velocity>
          </limit>
          <dynamics>
            <damping>0.01</damping>
            <friction>0.2</friction>
            <spring_reference>0</spring_reference>
            <spring_stiffness>0</spring_stiffness>
          </dynamics>
        </axis>
      </joint>
      <link name='rh_upper_leg_link'>
        <pose relative_to='rh_upper_leg_joint'>0 0 0 0 -0 0</pose>
        <inertial>
          <pose>-0.00374 0.0223 -0.0327 0 -0 0</pose>
          <mass>1.152</mass>
          <inertia>
            <ixx>0.00584</ixx>
            <ixy>-8.72e-05</ixy>
            <ixz>-0.000289</ixz>
            <iyy>0.0058</iyy>
            <iyz>-0.000808</iyz>
            <izz>0.00103</izz>
          </inertia>
        </inertial>
        <collision name='rh_upper_leg_link_collision'>
          <pose>0 0 -0.1065 3.14159 1.57079 3.14159</pose>
          <geometry>
            <box>
              <size>0.213 0.0245 0.034</size>
            </box>
          </geometry>
          <surface>
            <contact>
              <ode>
                <kp>10000</kp>
                <kd>1</kd>
              </ode>
            </contact>
            <friction>
              <ode>
                <mu>0.2</mu>
                <mu2>0.2</mu2>
              </ode>
              <torsional>
                <ode/>
              </torsional>
            </friction>
            <bounce/>
          </surface>
          <max_contacts>10</max_contacts>
        </collision>
        <visual name='rh_upper_leg_link_visual'>
          <pose>0 0 0 0 -0 0</pose>
          <geometry>
            <mesh>
              <scale>1 1 1</scale>
              <uri>file:///workspace/comp0244-go2/install/go2_description/share/go2_description/meshes/thigh_mirror.dae</uri>
            </mesh>
          </geometry>
        </visual>
        <self_collide>1</self_collide>
        <enable_wind>0</enable_wind>
        <kinematic>0</kinematic>
      </link>
      <joint name='rh_lower_leg_joint' type='revolute'>
        <pose relative_to='rh_upper_leg_link'>0 0 -0.213 0 -0 0</pose>
        <parent>rh_upper_leg_link</parent>
        <child>rh_lower_leg_link</child>
        <axis>
          <xyz>0 1 0</xyz>
          <limit>
            <lower>-2.7227</lower>
            <upper>-0.83776</upper>
            <effort>35.55</effort>
            <velocity>20.06</velocity>
          </limit>
          <dynamics>
            <damping>0.01</damping>
            <friction>0.2</friction>
            <spring_reference>0</spring_reference>
            <spring_stiffness>0</spring_stiffness>
          </dynamics>
        </axis>
      </joint>
      <link name='rh_lower_leg_link'>
        <pose relative_to='rh_lower_leg_joint'>0 0 0 0 -0 0</pose>
        <inertial>
          <pose>0.003944 -0.000702 -0.142477 0 -0 0</pose>
          <mass>0.214</mass>
          <inertia>
            <ixx>0.00150432</ixx>
            <ixy>5.70698e-07</ixy>
            <ixz>-5.98808e-06</ixz>
            <iyy>0.00152557</iyy>
            <iyz>1.24056e-05</iyz>
            <izz>4.38377e-05</izz>
          </inertia>
        </inertial>
        <collision name='rh_lower_leg_link_collision'>
          <pose>0 0 -0.1065 3.14159 1.57079 3.14159</pose>
          <geometry>
            <box>
              <size>0.213 0.016 0.016</size>
            </box>
          </geometry>
          <surface>
            <contact>
              <ode/>
            </contact>
            <friction>
              <ode>
                <mu>0.2</mu>
                <mu2>0.2</mu2>
              </ode>
              <torsional>
                <ode/>
              </torsional>
            </friction>
            <bounce/>
          </surface>
          <max_contacts>10</max_contacts>
        </collision>
        <collision name='rh_lower_leg_link_fixed_joint_lump__rh_foot_link_collision_1'>
          <pose>0 0 -0.213 0 -0 0</pose>
          <geometry>
            <sphere>
              <radius>0.02</radius>
            </sphere>
          </geometry>
          <surface>
            <contact>
              <ode>
                <kp>10000</kp>
                <kd>1</kd>
              </ode>
            </contact>
            <friction>
              <ode>
                <mu>0.6</mu>
                <mu2>0.6</mu2>
              </ode>
              <torsional>
                <ode/>
              </torsional>
            </friction>
            <bounce/>
          </surface>
          <max_contacts>10</max_contacts>
        </collision>
        <visual name='rh_lower_leg_link_visual'>
          <pose>0 0 0 0 -0 0</pose>
          <geometry>
            <mesh>
              <scale>1 1 1</scale>
              <uri>file:///workspace/comp0244-go2/install/go2_description/share/go2_description/meshes/calf.dae</uri>
            </mesh>
          </geometry>
        </visual>
        <visual name='rh_lower_leg_link_fixed_joint_lump__rh_foot_link_visual_1'>
          <pose>0 0 -0.213 0 -0 0</pose>
          <geometry>
            <sphere>
              <radius>0.01</radius>
            </sphere>
          </geometry>
        </visual>
        <self_collide>1</self_collide>
        <self_collide>1</self_collide>
        <enable_wind>0</enable_wind>
        <kinematic>0</kinematic>
      </link>
      <plugin name='p3d_base_controller' filename='libgazebo_ros_p3d.so'>
        <ros>
          <remapping>odom:=odom/ground_truth</remapping>
        </ros>
        <body_name>base_link</body_name>
        <frame_name>world</frame_name>
        <update_rate>10.0</update_rate>
        <xyz_offset>0 0 0</xyz_offset>
        <rpy_offset>0 0 0</rpy_offset>
        <gaussian_noise>0.01</gaussian_noise>
      </plugin>
      <static>0</static>
      <plugin name='gazebo_ros2_control' filename='libgazebo_ros2_control.so'>
        <parameters>/workspace/comp0244-go2/install/go2_description/share/go2_description/config/ros_control/ros_control.yaml</parameters>
      </plugin>
      <pose>0 -3 0.275 0 -0 1.57</pose>
    </model>
  </world>
</sdf>
